Workbook

Sheet global_water_consumption.csv
A1: Country | B1: Year | C1: Total Water Consumption (Billion Cubic Meters) | D1: Per Capita Water Use (Liters per Day) | E1: Agricultural Water Use (%) | F1: Industrial Water Use (%) | G1: Household Water Use (%) | H1: Rainfall Impact (Annual Precipitation in mm) | I1: Groundwater Depletion Rate (%) | J1: Water Scarcity Level
A2: Argentina | B2: 2000 | C2: 481.49 | D2: 235.43143 | E2: 48.55 | F2: 20.844286 | G2: 30.1 | H2: 1288.6986 | I2: 3.2557143 | J2: Moderate
A3: Argentina | B3: 2001 | C3: 455.063 | D3: 299.551 | E3: 48.465 | F3: 26.943 | G3: 22.55 | H3: 1371.729 | I3: 3.12 | J3: Moderate
A4: Argentina | B4: 2002 | C4: 482.74923 | D4: 340.12462 | E4: 50.375385 | F4: 29.042308 | G4: 23.349231 | H4: 1590.3054 | I4: 2.7338462 | J4: Moderate
A5: Argentina | B5: 2003 | C5: 452.66 | D5: 326.75667 | E5: 49.086667 | F5: 30.476 | G5: 24.44 | H5: 1816.0127 | I5: 2.708 | J5: Moderate
A6: Argentina | B6: 2004 | C6: 634.566 | D6: 230.346 | E6: 38.67 | F6: 36.67 | G6: 23.924 | H6: 815.998 | I6: 1.902 | J6: Moderate
A7: Argentina | B7: 2005 | C7: 458.077 | D7: 265.012 | E7: 59.834 | F7: 29.288 | G7: 22.649 | H7: 1826.293 | I7: 2.724 | J7: Moderate
A8: Argentina | B8: 2006 | C8: 452.98333 | D8: 111.70833 | E8: 54.961667 | F8: 29.791667 | G8: 28.831667 | H8: 1318.9233 | I8: 3.1333333 | J8: Moderate
A9: Argentina | B9: 2007 | C9: 691.1025 | D9: 192.815 | E9: 41.655 | F9: 16.705 | G9: 20.31 | H9: 1500.8375 | I9: 3.5 | J9: Moderate
A10: Argentina | B10: 2008 | C10: 494.048 | D10: 230.443 | E10: 60.323 | F10: 24.483 | G10: 24.21 | H10: 1378.952 | I10: 3.006 | J10: Moderate
A11: Argentina | B11: 2009 | C11: 637.87833 | D11: 230.68167 | E11: 54.916667 | F11: 29.051667 | G11: 21.211667 | H11: 1141.9067 | I11: 2.3566667 | J11: Moderate
A12: Argentina | B12: 2010 | C12: 502.875 | D12: 216.807 | E12: 49.325 | F12: 23.932 | G12: 25.208 | H12: 1496.221 | I12: 2.671 | J12: Moderate
A13: Argentina | B13: 2011 | C13: 535.33687 | D13: 317.69375 | E13: 44.3875 | F13: 29.1575 | G13: 22.778125 | H13: 1814.8656 | I13: 2.955625 | J13: Moderate
... A501: USA | B501: 2024 | C501: 249.485 | D501: 186.374 | E501: 51.386 | F501: 24.769 | G501: 27.677 | H501: 1771.199 | I501: 1.638 | J501: High

Sheet KPI Summary
A1: Global Water Consumption - KPI Summary
A3: KPI | B3: RESULT
A4: Total Water Consumption | B4: =SUM(global_water_consumption.csv!C2:C1000) -> 250612.22
A5: Average Per Capita Water Use | B5: =AVERAGE(global_water_consumption.csv!D2:D1000) -> 276.00478
A6: Average Agricultural Water Use | B6: =AVERAGE(global_water_consumption.csv!E2:E1000) -> 50.180829
A7: Average Industrial Water Use | B7: =AVERAGE(global_water_consumption.csv!F2:F1000) -> 27.792837
A8: Average Household Water Use | B8: =AVERAGE(global_water_consumption.csv!G2:G1000) -> 24.832515
A9: Average Annual Precipitation | B9: =AVERAGE(global_water_consumption.csv!H1:H1000) -> 1544.8243
A10: Average groundwater depletion | B10: =AVERAGE(global_water_consumption.csv!I1:I1000) -> 2.5730371
A11: High Water Scarcity Records | B11: =COUNTIF(global_water_consumption.csv!J2:J1000, "High") -> 18

Sheet Pivot Table 1
A1: Country wise Total Water Consumption
A3: Country | B3: SUM of Total Water Consumption (Billion Cubic Meters)
A4: Argentina | B4: 13284.861
A5: Brazil | B5: 13263.287
A6: China | B6: 13133.597
A7: USA | B7: 13058.951
A8: Saudi Arabia | B8: 12966.079
A9: Germany | B9: 12668.589
A10: France | B10: 12596.116
A11: Japan | B11: 12585.683
A12: India | B12: 12581.663
A13: South Africa | B13: 12544.931
A14: Australia | B14: 12505.778
A15: Italy | B15: 12449.632
... A24: Grand Total | B24: 250612.22
A28: Year wise Water Consumption
A30: Year | B30: SUM of Total Water Consumption (Billion Cubic Meters)
A31: 2000 | B31: 10090.382
A32: 2001 | B32: 10061.072
A33: 2002 | B33: 9498.115
A34: 2003 | B34: 10186.876
A35: 2004 | B35: 10901.926
A36: 2005 | B36: 9124.7585
A37: 2006 | B37: 9852.5811
A38: 2007 | B38: 10351.436
A39: 2008 | B39: 11062.776
A40: 2009 | B40: 9397.981
A41: 2010 | B41: 9825.1152
A42: 2011 | B42: 10499.058
... A55: 2024 | B55: 9994.6166
A56: Grand Total | B56: 250612.22
A60: Country Wise Per Capta Water Use
A62: Country | B62: AVERAGE of Per Capita Water Use (Liters per Day)
A63: India | B63: 295.16807
A64: Italy | B64: 284.19626
A65: Turkey | B65: 281.70348
A66: UK | B66: 280.99844
A67: Russia | B67: 280.95933
A68: China | B68: 280.30733
A69: Mexico | B69: 278.89847
...

Sheet Analysis Table
A1: 1. Top 5 countries by total water consumption
A3: Country | B3: Total Water Consumption
A4: Argentina | B4: 13284.861
A5: Brazil | B5: 13263.287
A6: China | B6: 13133.597
A7: USA | B7: 13058.951
A8: Saudi Arabia | B8: 12966.079
A23: 2. Bottom 5 countries by total water consumption
A25: Country | B25: Total Water Consumption
A26: Spain | B26: 11796.579
A27: Turkey | B27: 11882.585
A28: Mexico | B28: 12058.054
A29: Indonesia | B29: 12151.267
A30: UK | B30: 12161.475
A46: 3.Year-wise total water consumption
A48: Year | B48: Total Water Consumption | C48: YOY Change %
A49: 2000 | B49: 10090.382
A50: 2001 | B50: 10061.072 | C50: =(B50-B49)/B49 -> -0.0029047519
A51: 2002 | B51: 9498.115 | C51: =(B51-B50)/B50 -> -0.055953977
A52: 2003 | B52: 10186.876 | C52: =(B52-B51)/B51 -> 0.072515524
A53: 2004 | B53: 10901.926 | C53: =(B53-B52)/B52 -> 0.070193298
A54: 2005 | B54: 9124.7585 | C54: =(B54-B53)/B53 -> -0.16301409
A55: 2006 | B55: 9852.5811 | C55: =(B55-B54)/B54 -> 0.079763491
A56: 2007 | B56: 10351.436 | C56: =(B56-B55)/B55 -> 0.050631884
A57: 2008 | B57: 11062.776 | C57: =(B57-B56)/B56 -> 0.068718959
A58: 2009 | B58: 9397.981 | C58: =(B58-B57)/B57 -> -0.15048617
A59: 2010 | B59: 9825.1152 | C59: =(B59-B58)/B58 -> 0.04544957
A60: 2011 | B60: 10499.058 | C60: =(B60-B59)/B59 -> 0.068593916
A61: 2012 | B61: 10681.365 | C61: =(B61-B60)/B60 -> 0.017364079
... A73: 2024 | B73: 9994.6166 | C73: =(B73-B72)/B72 -> 0.038164128
A76: 4. Top 5 Countries by Per Capita Water Use
A78: Country | B78: Per Capita Water Use
A79: India | B79: 295.16807
A80: Italy | B80: 284.19626
A81: Turkey | B81: 281.70348
A82: UK | B82: 280.99844
A83: Russia | B83: 280.95933
A100: 5. Top 5 Countries by Groundwater Depletion
A102: Country | B102: Groundwater Depletion
A103: Canada | B103: 2.8336408
...

Sheet Dashboard
A1: GLOBAL WATER CONSUMPTION DASHBOARD
A3: Total Water Consumption | C3: Average Per Capita Water Use | E3: Average Groundwater Depletion | G3: High Water Scarcity Records
A4: ='KPI Summary'!B4 -> 250612.22 | C4: =AVERAGE(global_water_consumption.csv!E1:E1000) -> 50.180829 | E4: ='KPI Summary'!B10 -> 2.5730371 | G4: 18
